2025-06-07 22:35:11,809 : ERROR : BINANCE: Failed to parse symbol information: 451 Client Error:  for url: https://api.binance.com/api/v3/exchangeInfo
Traceback (most recent call last):
  File "D:\Users\semic\Anaconda3\envs\qfi\Lib\site-packages\cryptofeed\exchange.py", line 103, in symbol_mapping
    data.append(cls.http_sync.read(addr, json=True, headers=headers, uuid=cls.id))
                ^^^^^^^^^^^^^^^^^^^^^^^^^^^^^^^^^^^^^^^^^^^^^^^^^^^^^^^^^^^^^^^^^
  File "D:\Users\semic\Anaconda3\envs\qfi\Lib\site-packages\cryptofeed\connection.py", line 57, in read
    return self.process_response(r, address, json=json, text=text, uuid=uuid)
           ^^^^^^^^^^^^^^^^^^^^^^^^^^^^^^^^^^^^^^^^^^^^^^^^^^^^^^^^^^^^^^^^^^
  File "D:\Users\semic\Anaconda3\envs\qfi\Lib\site-packages\cryptofeed\connection.py", line 47, in process_response
    r.raise_for_status()
  File "D:\Users\semic\Anaconda3\envs\qfi\Lib\site-packages\requests\models.py", line 1024, in raise_for_status
    raise HTTPError(http_error_msg, response=self)
requests.exceptions.HTTPError: 451 Client Error:  for url: https://api.binance.com/api/v3/exchangeInfo
2025-06-07 23:28:42,204 : ERROR : COINBASE: Failed to parse symbol information: 401 Client Error: Unauthorized for url: https://api.coinbase.com/api/v3/brokerage/products
Traceback (most recent call last):
  File "D:\Users\semic\Anaconda3\envs\qfi\Lib\site-packages\cryptofeed\exchange.py", line 103, in symbol_mapping
    data.append(cls.http_sync.read(addr, json=True, headers=headers, uuid=cls.id))
                ^^^^^^^^^^^^^^^^^^^^^^^^^^^^^^^^^^^^^^^^^^^^^^^^^^^^^^^^^^^^^^^^^
  File "D:\Users\semic\Anaconda3\envs\qfi\Lib\site-packages\cryptofeed\connection.py", line 57, in read
    return self.process_response(r, address, json=json, text=text, uuid=uuid)
           ^^^^^^^^^^^^^^^^^^^^^^^^^^^^^^^^^^^^^^^^^^^^^^^^^^^^^^^^^^^^^^^^^^
  File "D:\Users\semic\Anaconda3\envs\qfi\Lib\site-packages\cryptofeed\connection.py", line 47, in process_response
    r.raise_for_status()
  File "D:\Users\semic\Anaconda3\envs\qfi\Lib\site-packages\requests\models.py", line 1024, in raise_for_status
    raise HTTPError(http_error_msg, response=self)
requests.exceptions.HTTPError: 401 Client Error: Unauthorized for url: https://api.coinbase.com/api/v3/brokerage/products
2025-06-07 23:29:02,116 : ERROR : FH: Unhandled RuntimeError('This event loop is already running') - shutting down
Traceback (most recent call last):
  File "D:\Users\semic\Anaconda3\envs\qfi\Lib\site-packages\cryptofeed\feedhandler.py", line 151, in run
    loop.run_forever()
  File "D:\Users\semic\Anaconda3\envs\qfi\Lib\asyncio\windows_events.py", line 322, in run_forever
    super().run_forever()
  File "D:\Users\semic\Anaconda3\envs\qfi\Lib\asyncio\base_events.py", line 630, in run_forever
    self._check_running()
  File "D:\Users\semic\Anaconda3\envs\qfi\Lib\asyncio\base_events.py", line 622, in _check_running
    raise RuntimeError('This event loop is already running')
RuntimeError: This event loop is already running
2025-06-07 23:29:19,007 : ERROR : FH: Unhandled RuntimeError('This event loop is already running') - shutting down
Traceback (most recent call last):
  File "D:\Users\semic\Anaconda3\envs\qfi\Lib\site-packages\cryptofeed\feedhandler.py", line 151, in run
    loop.run_forever()
  File "D:\Users\semic\Anaconda3\envs\qfi\Lib\asyncio\windows_events.py", line 322, in run_forever
    super().run_forever()
  File "D:\Users\semic\Anaconda3\envs\qfi\Lib\asyncio\base_events.py", line 630, in run_forever
    self._check_running()
  File "D:\Users\semic\Anaconda3\envs\qfi\Lib\asyncio\base_events.py", line 622, in _check_running
    raise RuntimeError('This event loop is already running')
RuntimeError: This event loop is already running
2025-06-07 23:31:23,598 : ERROR : KRAKEN.ws.1: encountered an exception, reconnecting in 1.0 seconds
Traceback (most recent call last):
  File "D:\Users\semic\Anaconda3\envs\qfi\Lib\site-packages\arcticdb\version_store\_store.py", line 442, in _try_normalize
    item, norm_meta = self._normalizer.normalize(
                      ^^^^^^^^^^^^^^^^^^^^^^^^^^^
  File "D:\Users\semic\Anaconda3\envs\qfi\Lib\site-packages\arcticdb\version_store\_normalization.py", line 1245, in normalize
    return self._normalize(
           ^^^^^^^^^^^^^^^^
  File "D:\Users\semic\Anaconda3\envs\qfi\Lib\site-packages\arcticdb\version_store\_normalization.py", line 1185, in _normalize
    return normalizer(
           ^^^^^^^^^^^
  File "D:\Users\semic\Anaconda3\envs\qfi\Lib\site-packages\arcticdb\version_store\_normalization.py", line 953, in normalize
    columns, column_vals = _normalize_columns(
                           ^^^^^^^^^^^^^^^^^^^
  File "D:\Users\semic\Anaconda3\envs\qfi\Lib\site-packages\arcticdb\version_store\_normalization.py", line 556, in _normalize_columns
    _to_primitive(
  File "D:\Users\semic\Anaconda3\envs\qfi\Lib\site-packages\arcticdb\version_store\_normalization.py", line 296, in _to_primitive
    raise ArcticDbNotYetImplemented(
arcticdb.exceptions.ArcticDbNotYetImplemented: Failed to normalize column 'amount' with dtype 'object'. Found first non-null value of type '<class 'decimal.Decimal'>', but only strings, unicode, and Timestamps are supported. Do you have mixed dtypes in your column?

During handling of the above exception, another exception occurred:

Traceback (most recent call last):
  File "D:\Users\semic\Anaconda3\envs\qfi\Lib\site-packages\cryptofeed\connection_handler.py", line 65, in _create_connection
    await self._handler(connection, self.handler)
  File "D:\Users\semic\Anaconda3\envs\qfi\Lib\site-packages\cryptofeed\connection_handler.py", line 99, in _handler
    await handler(message, connection, self.conn.last_message)
  File "D:\Users\semic\Anaconda3\envs\qfi\Lib\site-packages\cryptofeed\exchanges\kraken.py", line 207, in message_handler
    await self._trade(msg, pair, timestamp)
  File "D:\Users\semic\Anaconda3\envs\qfi\Lib\site-packages\cryptofeed\exchanges\kraken.py", line 115, in _trade
    await self.callback(TRADES, t, timestamp)
  File "D:\Users\semic\Anaconda3\envs\qfi\Lib\site-packages\cryptofeed\feed.py", line 258, in callback
    await cb(obj, receipt_timestamp)
  File "C:\Users\semic\OneDrive\Desktop\Crypto_Data_Collection\data.py", line 55, in custom_arctic_callback
    lib.append(trade.symbol, df)
  File "D:\Users\semic\Anaconda3\envs\qfi\Lib\site-packages\arcticdb\version_store\library.py", line 1185, in append
    return self._nvs.append(
           ^^^^^^^^^^^^^^^^^
  File "D:\Users\semic\Anaconda3\envs\qfi\Lib\site-packages\arcticdb\version_store\_store.py", line 770, in append
    udm, item, norm_meta = self._try_normalize(
                           ^^^^^^^^^^^^^^^^^^^^
  File "D:\Users\semic\Anaconda3\envs\qfi\Lib\site-packages\arcticdb\version_store\_store.py", line 453, in _try_normalize
    raise ArcticDbNotYetImplemented(
arcticdb.exceptions.ArcticDbNotYetImplemented: Not supported: normalizing, symbol: BTC-USD, Reason: Failed to normalize column 'amount' with dtype 'object'. Found first non-null value of type '<class 'decimal.Decimal'>', but only strings, unicode, and Timestamps are supported. Do you have mixed dtypes in your column?, Data must be normalizable to be appended to existing data.
2025-06-07 23:31:32,572 : ERROR : KRAKEN.ws.1: encountered an exception, reconnecting in 1.0 seconds
Traceback (most recent call last):
  File "D:\Users\semic\Anaconda3\envs\qfi\Lib\site-packages\arcticdb\version_store\_store.py", line 442, in _try_normalize
    item, norm_meta = self._normalizer.normalize(
                      ^^^^^^^^^^^^^^^^^^^^^^^^^^^
  File "D:\Users\semic\Anaconda3\envs\qfi\Lib\site-packages\arcticdb\version_store\_normalization.py", line 1245, in normalize
    return self._normalize(
           ^^^^^^^^^^^^^^^^
  File "D:\Users\semic\Anaconda3\envs\qfi\Lib\site-packages\arcticdb\version_store\_normalization.py", line 1185, in _normalize
    return normalizer(
           ^^^^^^^^^^^
  File "D:\Users\semic\Anaconda3\envs\qfi\Lib\site-packages\arcticdb\version_store\_normalization.py", line 953, in normalize
    columns, column_vals = _normalize_columns(
                           ^^^^^^^^^^^^^^^^^^^
  File "D:\Users\semic\Anaconda3\envs\qfi\Lib\site-packages\arcticdb\version_store\_normalization.py", line 556, in _normalize_columns
    _to_primitive(
  File "D:\Users\semic\Anaconda3\envs\qfi\Lib\site-packages\arcticdb\version_store\_normalization.py", line 296, in _to_primitive
    raise ArcticDbNotYetImplemented(
arcticdb.exceptions.ArcticDbNotYetImplemented: Failed to normalize column 'amount' with dtype 'object'. Found first non-null value of type '<class 'decimal.Decimal'>', but only strings, unicode, and Timestamps are supported. Do you have mixed dtypes in your column?

During handling of the above exception, another exception occurred:

Traceback (most recent call last):
  File "D:\Users\semic\Anaconda3\envs\qfi\Lib\site-packages\cryptofeed\connection_handler.py", line 65, in _create_connection
    await self._handler(connection, self.handler)
  File "D:\Users\semic\Anaconda3\envs\qfi\Lib\site-packages\cryptofeed\connection_handler.py", line 99, in _handler
    await handler(message, connection, self.conn.last_message)
  File "D:\Users\semic\Anaconda3\envs\qfi\Lib\site-packages\cryptofeed\exchanges\kraken.py", line 207, in message_handler
    await self._trade(msg, pair, timestamp)
  File "D:\Users\semic\Anaconda3\envs\qfi\Lib\site-packages\cryptofeed\exchanges\kraken.py", line 115, in _trade
    await self.callback(TRADES, t, timestamp)
  File "D:\Users\semic\Anaconda3\envs\qfi\Lib\site-packages\cryptofeed\feed.py", line 258, in callback
    await cb(obj, receipt_timestamp)
  File "C:\Users\semic\OneDrive\Desktop\Crypto_Data_Collection\data.py", line 55, in custom_arctic_callback
    lib.append(trade.symbol, df)
  File "D:\Users\semic\Anaconda3\envs\qfi\Lib\site-packages\arcticdb\version_store\library.py", line 1185, in append
    return self._nvs.append(
           ^^^^^^^^^^^^^^^^^
  File "D:\Users\semic\Anaconda3\envs\qfi\Lib\site-packages\arcticdb\version_store\_store.py", line 770, in append
    udm, item, norm_meta = self._try_normalize(
                           ^^^^^^^^^^^^^^^^^^^^
  File "D:\Users\semic\Anaconda3\envs\qfi\Lib\site-packages\arcticdb\version_store\_store.py", line 453, in _try_normalize
    raise ArcticDbNotYetImplemented(
arcticdb.exceptions.ArcticDbNotYetImplemented: Not supported: normalizing, symbol: BTC-USD, Reason: Failed to normalize column 'amount' with dtype 'object'. Found first non-null value of type '<class 'decimal.Decimal'>', but only strings, unicode, and Timestamps are supported. Do you have mixed dtypes in your column?, Data must be normalizable to be appended to existing data.
2025-06-07 23:33:24,949 : ERROR : KRAKEN.ws.1: encountered an exception, reconnecting in 1.0 seconds
Traceback (most recent call last):
  File "D:\Users\semic\Anaconda3\envs\qfi\Lib\site-packages\arcticdb\version_store\_store.py", line 442, in _try_normalize
    item, norm_meta = self._normalizer.normalize(
                      ^^^^^^^^^^^^^^^^^^^^^^^^^^^
  File "D:\Users\semic\Anaconda3\envs\qfi\Lib\site-packages\arcticdb\version_store\_normalization.py", line 1245, in normalize
    return self._normalize(
           ^^^^^^^^^^^^^^^^
  File "D:\Users\semic\Anaconda3\envs\qfi\Lib\site-packages\arcticdb\version_store\_normalization.py", line 1185, in _normalize
    return normalizer(
           ^^^^^^^^^^^
  File "D:\Users\semic\Anaconda3\envs\qfi\Lib\site-packages\arcticdb\version_store\_normalization.py", line 953, in normalize
    columns, column_vals = _normalize_columns(
                           ^^^^^^^^^^^^^^^^^^^
  File "D:\Users\semic\Anaconda3\envs\qfi\Lib\site-packages\arcticdb\version_store\_normalization.py", line 556, in _normalize_columns
    _to_primitive(
  File "D:\Users\semic\Anaconda3\envs\qfi\Lib\site-packages\arcticdb\version_store\_normalization.py", line 296, in _to_primitive
    raise ArcticDbNotYetImplemented(
arcticdb.exceptions.ArcticDbNotYetImplemented: Failed to normalize column 'amount' with dtype 'object'. Found first non-null value of type '<class 'decimal.Decimal'>', but only strings, unicode, and Timestamps are supported. Do you have mixed dtypes in your column?

During handling of the above exception, another exception occurred:

Traceback (most recent call last):
  File "D:\Users\semic\Anaconda3\envs\qfi\Lib\site-packages\cryptofeed\connection_handler.py", line 65, in _create_connection
    await self._handler(connection, self.handler)
  File "D:\Users\semic\Anaconda3\envs\qfi\Lib\site-packages\cryptofeed\connection_handler.py", line 99, in _handler
    await handler(message, connection, self.conn.last_message)
  File "D:\Users\semic\Anaconda3\envs\qfi\Lib\site-packages\cryptofeed\exchanges\kraken.py", line 207, in message_handler
    await self._trade(msg, pair, timestamp)
  File "D:\Users\semic\Anaconda3\envs\qfi\Lib\site-packages\cryptofeed\exchanges\kraken.py", line 115, in _trade
    await self.callback(TRADES, t, timestamp)
  File "D:\Users\semic\Anaconda3\envs\qfi\Lib\site-packages\cryptofeed\feed.py", line 258, in callback
    await cb(obj, receipt_timestamp)
  File "C:\Users\semic\OneDrive\Desktop\Crypto_Data_Collection\data.py", line 55, in custom_arctic_callback
    lib.append(trade.symbol, df)
  File "D:\Users\semic\Anaconda3\envs\qfi\Lib\site-packages\arcticdb\version_store\library.py", line 1185, in append
    return self._nvs.append(
           ^^^^^^^^^^^^^^^^^
  File "D:\Users\semic\Anaconda3\envs\qfi\Lib\site-packages\arcticdb\version_store\_store.py", line 770, in append
    udm, item, norm_meta = self._try_normalize(
                           ^^^^^^^^^^^^^^^^^^^^
  File "D:\Users\semic\Anaconda3\envs\qfi\Lib\site-packages\arcticdb\version_store\_store.py", line 453, in _try_normalize
    raise ArcticDbNotYetImplemented(
arcticdb.exceptions.ArcticDbNotYetImplemented: Not supported: normalizing, symbol: BTC-USD, Reason: Failed to normalize column 'amount' with dtype 'object'. Found first non-null value of type '<class 'decimal.Decimal'>', but only strings, unicode, and Timestamps are supported. Do you have mixed dtypes in your column?, Data must be normalizable to be appended to existing data.
2025-06-07 23:34:47,778 : ERROR : KRAKEN.ws.1: encountered an exception, reconnecting in 1.0 seconds
Traceback (most recent call last):
  File "D:\Users\semic\Anaconda3\envs\qfi\Lib\site-packages\cryptofeed\connection_handler.py", line 65, in _create_connection
    await self._handler(connection, self.handler)
  File "D:\Users\semic\Anaconda3\envs\qfi\Lib\site-packages\cryptofeed\connection_handler.py", line 99, in _handler
    await handler(message, connection, self.conn.last_message)
  File "D:\Users\semic\Anaconda3\envs\qfi\Lib\site-packages\cryptofeed\exchanges\kraken.py", line 207, in message_handler
    await self._trade(msg, pair, timestamp)
  File "D:\Users\semic\Anaconda3\envs\qfi\Lib\site-packages\cryptofeed\exchanges\kraken.py", line 115, in _trade
    await self.callback(TRADES, t, timestamp)
  File "D:\Users\semic\Anaconda3\envs\qfi\Lib\site-packages\cryptofeed\feed.py", line 258, in callback
    await cb(obj, receipt_timestamp)
TypeError: object NoneType can't be used in 'await' expression
2025-06-08 20:46:42,909 : ERROR : COINBASE: Failed to parse symbol information: 401 Client Error: Unauthorized for url: https://api.coinbase.com/api/v3/brokerage/products
Traceback (most recent call last):
  File "D:\Users\semic\Anaconda3\envs\qfi\Lib\site-packages\cryptofeed\exchange.py", line 103, in symbol_mapping
    data.append(cls.http_sync.read(addr, json=True, headers=headers, uuid=cls.id))
                ^^^^^^^^^^^^^^^^^^^^^^^^^^^^^^^^^^^^^^^^^^^^^^^^^^^^^^^^^^^^^^^^^
  File "D:\Users\semic\Anaconda3\envs\qfi\Lib\site-packages\cryptofeed\connection.py", line 57, in read
    return self.process_response(r, address, json=json, text=text, uuid=uuid)
           ^^^^^^^^^^^^^^^^^^^^^^^^^^^^^^^^^^^^^^^^^^^^^^^^^^^^^^^^^^^^^^^^^^
  File "D:\Users\semic\Anaconda3\envs\qfi\Lib\site-packages\cryptofeed\connection.py", line 47, in process_response
    r.raise_for_status()
  File "D:\Users\semic\Anaconda3\envs\qfi\Lib\site-packages\requests\models.py", line 1024, in raise_for_status
    raise HTTPError(http_error_msg, response=self)
requests.exceptions.HTTPError: 401 Client Error: Unauthorized for url: https://api.coinbase.com/api/v3/brokerage/products
2025-06-08 20:49:10,744 : ERROR : COINBASE: Failed to parse symbol information: 401 Client Error: Unauthorized for url: https://api.coinbase.com/api/v3/brokerage/products
Traceback (most recent call last):
  File "D:\Users\semic\Anaconda3\envs\qfi\Lib\site-packages\cryptofeed\exchange.py", line 103, in symbol_mapping
    data.append(cls.http_sync.read(addr, json=True, headers=headers, uuid=cls.id))
                ^^^^^^^^^^^^^^^^^^^^^^^^^^^^^^^^^^^^^^^^^^^^^^^^^^^^^^^^^^^^^^^^^
  File "D:\Users\semic\Anaconda3\envs\qfi\Lib\site-packages\cryptofeed\connection.py", line 57, in read
    return self.process_response(r, address, json=json, text=text, uuid=uuid)
           ^^^^^^^^^^^^^^^^^^^^^^^^^^^^^^^^^^^^^^^^^^^^^^^^^^^^^^^^^^^^^^^^^^
  File "D:\Users\semic\Anaconda3\envs\qfi\Lib\site-packages\cryptofeed\connection.py", line 47, in process_response
    r.raise_for_status()
  File "D:\Users\semic\Anaconda3\envs\qfi\Lib\site-packages\requests\models.py", line 1024, in raise_for_status
    raise HTTPError(http_error_msg, response=self)
requests.exceptions.HTTPError: 401 Client Error: Unauthorized for url: https://api.coinbase.com/api/v3/brokerage/products
2025-06-14 21:24:27,281 : WARNING : BITSTAMP.ws.7: received no messages within timeout, restarting connection
2025-06-14 21:26:33,184 : WARNING : BITSTAMP.ws.7: received no messages within timeout, restarting connection
